2021-03-15 20:40:01.546 7666 DEBUG oslo.messaging._drivers.impl_rabbit [-] [87212747-a33a-4aef-879f-b9f696c43766] Queue.declare: reply_0a73a4b644ce469590090d1c6c51d671 declare /usr/lib/python3/dist-packages/oslo_messaging/_drivers/impl_rabbit.py:275
2021-03-15 20:40:01.585 7666 INFO oslo.messaging._drivers.impl_rabbit [-] [87212747-a33a-4aef-879f-b9f696c43766] Reconnected to AMQP server on 10.5.1.98:5672 via [amqp] client with port 58464.
2021-03-15 20:40:01.635 7666 DEBUG oslo_policy.policy [req-f9af9858-199b-48cb-9c1e-7a96019d1b8a cc2a8c1407bd4b4197b7d3f8665c3d51 9e4ea561f9be4a079c5fb8c31f7c1747 - bdadb8e94db84edbac317f26ce13c48e bdadb8e94db84edbac317f26ce13c48e] enforce: rule="os_compute_api:os-attach-interfaces:delete" creds={"domain_id": null, "is_admin": true, "is_admin_project": false, "project_domain_id": "bdadb8e94db84edbac317f26ce13c48e", "project_id": "9e4ea561f9be4a079c5fb8c31f7c1747", "roles": ["load-balancer_quota_admin", "load-balancer_admin", "reader", "member", "load-balancer_global_observer", "load-balancer_observer", "load-balancer_member", "Admin"], "service_project_domain_id": null, "service_project_id": null, "service_roles": [], "service_user_domain_id": null, "service_user_id": null, "system_scope": null, "user_domain_id": "bdadb8e94db84edbac317f26ce13c48e", "user_id": "cc2a8c1407bd4b4197b7d3f8665c3d51"} target={"project_id": "9e4ea561f9be4a079c5fb8c31f7c1747"} enforce /usr/lib/python3/dist-packages/oslo_policy/policy.py:951
2021-03-15 20:40:01.681 7666 DEBUG oslo_messaging._drivers.amqpdriver [req-f9af9858-199b-48cb-9c1e-7a96019d1b8a cc2a8c1407bd4b4197b7d3f8665c3d51 9e4ea561f9be4a079c5fb8c31f7c1747 - bdadb8e94db84edbac317f26ce13c48e bdadb8e94db84edbac317f26ce13c48e] CAST unique_id: 6c3fa1cd647441469d228f90d6df9252 exchange 'nova' topic 'compute.juju-eda7c1-lp1916761-b-u-6.cloud.sts' _send /usr/lib/python3/dist-packages/oslo_messaging/_drivers/amqpdriver.py:635
2021-03-15 20:40:03.928 7667 DEBUG oslo.messaging._drivers.impl_rabbit [-] [70082dd8-eb41-4827-9c6c-72ea3577c043] Received recoverable error from kombu: on_error /usr/lib/python3/dist-packages/oslo_messaging/_drivers/impl_rabbit.py:745
2021-03-15 20:40:03.928 7667 ERROR oslo.messaging._drivers.impl_rabbit Traceback (most recent call last):
2021-03-15 20:40:03.928 7667 ERROR oslo.messaging._drivers.impl_rabbit   File "/usr/lib/python3/dist-packages/kombu/connection.py", line 518, in _ensured
2021-03-15 20:40:03.928 7667 ERROR oslo.messaging._drivers.impl_rabbit     return fun(*args, **kwargs)
2021-03-15 20:40:03.928 7667 ERROR oslo.messaging._drivers.impl_rabbit   File "/usr/lib/python3/dist-packages/kombu/connection.py", line 594, in __call__
2021-03-15 20:40:03.928 7667 ERROR oslo.messaging._drivers.impl_rabbit     return fun(*args, channel=channels[0], **kwargs), channels[0]
2021-03-15 20:40:03.928 7667 ERROR oslo.messaging._drivers.impl_rabbit   File "/usr/lib/python3/dist-packages/oslo_messaging/_drivers/impl_rabbit.py", line 796, in execute_method
2021-03-15 20:40:03.928 7667 ERROR oslo.messaging._drivers.impl_rabbit     method()
2021-03-15 20:40:03.928 7667 ERROR oslo.messaging._drivers.impl_rabbit   File "/usr/lib/python3/dist-packages/oslo_messaging/_drivers/impl_rabbit.py", line 1095, in _consume
2021-03-15 20:40:03.928 7667 ERROR oslo.messaging._drivers.impl_rabbit     self.connection.drain_events(timeout=poll_timeout)
2021-03-15 20:40:03.928 7667 ERROR oslo.messaging._drivers.impl_rabbit   File "/usr/lib/python3/dist-packages/kombu/connection.py", line 323, in drain_events
2021-03-15 20:40:03.928 7667 ERROR oslo.messaging._drivers.impl_rabbit     return self.transport.drain_events(self.connection, **kwargs)
2021-03-15 20:40:03.928 7667 ERROR oslo.messaging._drivers.impl_rabbit   File "/usr/lib/python3/dist-packages/kombu/transport/pyamqp.py", line 103, in drain_events
2021-03-15 20:40:03.928 7667 ERROR oslo.messaging._drivers.impl_rabbit     return connection.drain_events(**kwargs)
2021-03-15 20:40:03.928 7667 ERROR oslo.messaging._drivers.impl_rabbit   File "/usr/lib/python3/dist-packages/amqp/connection.py", line 505, in drain_events
2021-03-15 20:40:03.928 7667 ERROR oslo.messaging._drivers.impl_rabbit     while not self.blocking_read(timeout):
2021-03-15 20:40:03.928 7667 ERROR oslo.messaging._drivers.impl_rabbit   File "/usr/lib/python3/dist-packages/amqp/connection.py", line 510, in blocking_read
2021-03-15 20:40:03.928 7667 ERROR oslo.messaging._drivers.impl_rabbit     frame = self.transport.read_frame()
2021-03-15 20:40:03.928 7667 ERROR oslo.messaging._drivers.impl_rabbit   File "/usr/lib/python3/dist-packages/amqp/transport.py", line 252, in read_frame
2021-03-15 20:40:03.928 7667 ERROR oslo.messaging._drivers.impl_rabbit     frame_header = read(7, True)
2021-03-15 20:40:03.928 7667 ERROR oslo.messaging._drivers.impl_rabbit   File "/usr/lib/python3/dist-packages/amqp/transport.py", line 446, in _read
2021-03-15 20:40:03.928 7667 ERROR oslo.messaging._drivers.impl_rabbit     raise IOError('Server unexpectedly closed connection')
2021-03-15 20:40:03.928 7667 ERROR oslo.messaging._drivers.impl_rabbit OSError: Server unexpectedly closed connection
2021-03-15 20:40:03.928 7667 ERROR oslo.messaging._drivers.impl_rabbit 
2021-03-15 20:40:03.933 7667 DEBUG oslo.messaging._drivers.impl_rabbit [-] [70082dd8-eb41-4827-9c6c-72ea3577c043] Received recoverable error from kombu: on_error /usr/lib/python3/dist-packages/oslo_messaging/_drivers/impl_rabbit.py:745
2021-03-15 20:40:03.933 7667 ERROR oslo.messaging._drivers.impl_rabbit Traceback (most recent call last):
2021-03-15 20:40:03.933 7667 ERROR oslo.messaging._drivers.impl_rabbit   File "/usr/lib/python3/dist-packages/kombu/connection.py", line 518, in _ensured
2021-03-15 20:40:03.933 7667 ERROR oslo.messaging._drivers.impl_rabbit     return fun(*args, **kwargs)
2021-03-15 20:40:03.933 7667 ERROR oslo.messaging._drivers.impl_rabbit   File "/usr/lib/python3/dist-packages/kombu/connection.py", line 594, in __call__
2021-03-15 20:40:03.933 7667 ERROR oslo.messaging._drivers.impl_rabbit     return fun(*args, channel=channels[0], **kwargs), channels[0]
2021-03-15 20:40:03.933 7667 ERROR oslo.messaging._drivers.impl_rabbit   File "/usr/lib/python3/dist-packages/oslo_messaging/_drivers/impl_rabbit.py", line 796, in execute_method
2021-03-15 20:40:03.933 7667 ERROR oslo.messaging._drivers.impl_rabbit     method()
2021-03-15 20:40:03.933 7667 ERROR oslo.messaging._drivers.impl_rabbit   File "/usr/lib/python3/dist-packages/oslo_messaging/_drivers/impl_rabbit.py", line 1077, in _consume
2021-03-15 20:40:03.933 7667 ERROR oslo.messaging._drivers.impl_rabbit     raise self.connection.recoverable_connection_errors[0]
2021-03-15 20:40:03.933 7667 ERROR oslo.messaging._drivers.impl_rabbit amqp.exceptions.RecoverableConnectionError: <RecoverableConnectionError: unknown error>
2021-03-15 20:40:03.933 7667 ERROR oslo.messaging._drivers.impl_rabbit 
2021-03-15 20:40:03.934 7667 ERROR oslo.messaging._drivers.impl_rabbit [-] [70082dd8-eb41-4827-9c6c-72ea3577c043] AMQP server on 10.5.1.98:5672 is unreachable: <RecoverableConnectionError: unknown error>. Trying again in 1 seconds.: amqp.exceptions.RecoverableConnectionError: <RecoverableConnectionError: unknown error>
2021-03-15 20:40:03.935 7667 DEBUG oslo.messaging._drivers.impl_rabbit [-] Exception _heartbeat_thread_job /usr/lib/python3/dist-packages/oslo_messaging/_drivers/impl_rabbit.py:1022
2021-03-15 20:40:03.935 7667 ERROR oslo.messaging._drivers.impl_rabbit Traceback (most recent call last):
2021-03-15 20:40:03.935 7667 ERROR oslo.messaging._drivers.impl_rabbit   File "/usr/lib/python3/dist-packages/oslo_messaging/_drivers/impl_rabbit.py", line 993, in _heartbeat_thread_job
2021-03-15 20:40:03.935 7667 ERROR oslo.messaging._drivers.impl_rabbit     self._heartbeat_check()
2021-03-15 20:40:03.935 7667 ERROR oslo.messaging._drivers.impl_rabbit   File "/usr/lib/python3/dist-packages/oslo_messaging/_drivers/impl_rabbit.py", line 959, in _heartbeat_check
2021-03-15 20:40:03.935 7667 ERROR oslo.messaging._drivers.impl_rabbit     self.connection.heartbeat_check(rate=self.heartbeat_rate)
2021-03-15 20:40:03.935 7667 ERROR oslo.messaging._drivers.impl_rabbit   File "/usr/lib/python3/dist-packages/kombu/connection.py", line 312, in heartbeat_check
2021-03-15 20:40:03.935 7667 ERROR oslo.messaging._drivers.impl_rabbit     return self.transport.heartbeat_check(self.connection, rate=rate)
2021-03-15 20:40:03.935 7667 ERROR oslo.messaging._drivers.impl_rabbit   File "/usr/lib/python3/dist-packages/kombu/transport/pyamqp.py", line 149, in heartbeat_check
2021-03-15 20:40:03.935 7667 ERROR oslo.messaging._drivers.impl_rabbit     return connection.heartbeat_tick(rate=rate)
2021-03-15 20:40:03.935 7667 ERROR oslo.messaging._drivers.impl_rabbit   File "/usr/lib/python3/dist-packages/amqp/connection.py", line 749, in heartbeat_tick
2021-03-15 20:40:03.935 7667 ERROR oslo.messaging._drivers.impl_rabbit     raise ConnectionForced('Too many heartbeats missed')
2021-03-15 20:40:03.935 7667 ERROR oslo.messaging._drivers.impl_rabbit amqp.exceptions.ConnectionForced: Too many heartbeats missed
2021-03-15 20:40:03.935 7667 ERROR oslo.messaging._drivers.impl_rabbit 
2021-03-15 20:40:03.938 7667 INFO oslo.messaging._drivers.impl_rabbit [-] A recoverable connection/channel error occurred, trying to reconnect: [Errno 104] Connection reset by peer
2021-03-15 20:40:04.582 7667 DEBUG oslo_policy.policy [req-310c5466-3953-49e4-b67c-5272a4d918cb b31d7231211f4845869c5c63a4bedf65 9e4ea561f9be4a079c5fb8c31f7c1747 - bdadb8e94db84edbac317f26ce13c48e bdadb8e94db84edbac317f26ce13c48e] enforce: rule="context_is_admin" creds={"domain_id": null, "is_admin": null, "is_admin_project": false, "project_domain_id": "bdadb8e94db84edbac317f26ce13c48e", "project_id": "9e4ea561f9be4a079c5fb8c31f7c1747", "roles": ["Admin", "reader", "member"], "service_project_domain_id": null, "service_project_id": null, "service_roles": [], "service_user_domain_id": null, "service_user_id": null, "system_scope": null, "user_domain_id": "bdadb8e94db84edbac317f26ce13c48e", "user_id": "b31d7231211f4845869c5c63a4bedf65"} target={"project_id": "9e4ea561f9be4a079c5fb8c31f7c1747", "user_id": "b31d7231211f4845869c5c63a4bedf65"} enforce /usr/lib/python3/dist-packages/oslo_policy/policy.py:951
2021-03-15 20:40:04.598 7667 DEBUG nova.api.openstack.wsgi [req-310c5466-3953-49e4-b67c-5272a4d918cb b31d7231211f4845869c5c63a4bedf65 9e4ea561f9be4a079c5fb8c31f7c1747 - bdadb8e94db84edbac317f26ce13c48e bdadb8e94db84edbac317f26ce13c48e] Action: 'create', calling method: <bound method ServerExternalEventsController.create of <nova.api.openstack.compute.server_external_events.ServerExternalEventsController object at 0x7f00608dbcc0>>, body: {"events": [{"name": "network-changed", "server_uuid": "6cf7f22e-3b9d-43a0-a452-205dc8fb2046", "tag": "c5c02cbf-cb22-4d50-82b3-0727b42313b4"}]} _process_stack /usr/lib/python3/dist-packages/nova/api/openstack/wsgi.py:520
2021-03-15 20:40:04.613 7667 DEBUG oslo_policy.policy [req-310c5466-3953-49e4-b67c-5272a4d918cb b31d7231211f4845869c5c63a4bedf65 9e4ea561f9be4a079c5fb8c31f7c1747 - bdadb8e94db84edbac317f26ce13c48e bdadb8e94db84edbac317f26ce13c48e] enforce: rule="os_compute_api:os-server-external-events:create" creds={"domain_id": null, "is_admin": true, "is_admin_project": false, "project_domain_id": "bdadb8e94db84edbac317f26ce13c48e", "project_id": "9e4ea561f9be4a079c5fb8c31f7c1747", "roles": ["Admin", "reader", "member"], "service_project_domain_id": null, "service_project_id": null, "service_roles": [], "service_user_domain_id": null, "service_user_id": null, "system_scope": null, "user_domain_id": "bdadb8e94db84edbac317f26ce13c48e", "user_id": "b31d7231211f4845869c5c63a4bedf65"} target={} enforce /usr/lib/python3/dist-packages/oslo_policy/policy.py:951
2021-03-15 20:40:04.641 7667 DEBUG oslo_concurrency.lockutils [req-310c5466-3953-49e4-b67c-5272a4d918cb b31d7231211f4845869c5c63a4bedf65 9e4ea561f9be4a079c5fb8c31f7c1747 - bdadb8e94db84edbac317f26ce13c48e bdadb8e94db84edbac317f26ce13c48e] Lock "dce4b1bd-8554-472b-9f84-db279ffddc48" acquired by "nova.context.set_target_cell.<locals>.get_or_set_cached_cell_and_set_connections" :: waited 0.000s inner /usr/lib/python3/dist-packages/oslo_concurrency/lockutils.py:358
2021-03-15 20:40:04.642 7667 DEBUG oslo_concurrency.lockutils [req-310c5466-3953-49e4-b67c-5272a4d918cb b31d7231211f4845869c5c63a4bedf65 9e4ea561f9be4a079c5fb8c31f7c1747 - bdadb8e94db84edbac317f26ce13c48e bdadb8e94db84edbac317f26ce13c48e] Lock "dce4b1bd-8554-472b-9f84-db279ffddc48" released by "nova.context.set_target_cell.<locals>.get_or_set_cached_cell_and_set_connections" :: held 0.000s inner /usr/lib/python3/dist-packages/oslo_concurrency/lockutils.py:370